Workbook

Sheet Cover
A2: 🏢 COMPANY HEALTH & RED-FLAG SCANNER
A3: Quantitative screening of 600 US-listed companies · SEC EDGAR XBRL data · 5 bankruptcy models · 6 earnings-quality models · 80+ financial ratios
A5: 600 companies · Data as of July 2026 | G5: Auto-generated 2026-07-09 10:08
A9: 600 | C9: 5 | E9: 6 | G9: 80+ | I9: 45+
A10: Companies Scanned | C10: Bankruptcy Models | E10: Earnings-Quality Models | G10: Financial Ratios | I10: Input Variables
A13: WHAT THIS WORKBOOK TESTS
A15: TEST 1 — SOLVENCY | G15: Altman Z-Score · 3 variants
A16: Can the company pay its bills? Classifies each firm as Safe / Grey Zone / Distress using working capital, retained earnings, EBIT, equity value, and revenue. Three variants cover public, private, and non-manufacturing companies.
A18: TEST 2 — FUNDAMENTALS | G18: Piotroski F-Score
A19: Is the business actually getting stronger? Nine binary yes/no checks across profitability (ROA, CFO), leverage (debt trend, dilution), and efficiency (gross margin, asset turnover). Score 0-9: 7+ = strong, 3 or less = weak.
A21: TEST 3 — EARNINGS QUALITY | G21: Beneish M · Dechow F · Sloan Accrual
A22: Are the numbers real? Beneish uses 8 accounting indices to flag manipulation. Dechow estimates SEC enforcement probability. Sloan measures accrual quality — high accruals predict future earnings disappointments.
A24: TEST 4 — CREATIVE ACCOUNTING | G24: Montier C-Score · Lev & Thiagarajan
A25: Six binary flags (NI vs CFO gap, DSO/DIO/DPO trends, D&A ratio, asset bloat) plus six fundamental quality signals. Catches companies managing expectations through accounting choices rather than genuine improvement.
A27: TEST 5 — REVENUE QUALITY | G27: Revenue Quality Index (RQI)
A28: Is revenue actually turning into cash? Tracks receivables growth vs revenue growth, cash collection rate, and deferred revenue trends. High score = cash-backed. Low score = paper profits at risk of reversal.
A31: WORKBOOK NAVIGATION
A33: Inputs | B33: Raw SEC EDGAR financial data for all 600 companies · 77 input fields per company
A35: Ratios_Scores | B35: 5 bankruptcy models + 80+ computed ratios: Z68, Z', Z'', Springate, Zmijewski, Piotroski
A37: Fraud_Detection | B37: 6 fraud models: Beneish M, Dechow F, Montier C, Sloan Accrual, LT Signals, Revenue Quality
A39: Industry_Benchmarks | B39: Sector peer medians for 11 GICS sectors — colour-coded vs Damodaran / FactSet standards
A41: Summary_Rank | B41: All 600 companies ranked by composite Health Score with every model flag in one view
A43: Company_Card | B43: Single-company deep-dive: dropdown selects any of 600 tickers · live ratios · automated analysis
A45: Fraud_Card | B45: Fraud-focused card: all 6 model components · sector caveats · investigation guide
A48: DISCLAIMER
A49: For analytical screening only — not investment advice. Past model performance does not guarantee future results.
A50: All financial data from most recent 10-K filings via SEC EDGAR XBRL. Accuracy depends on company disclosures.
A51: Quantitative models have known limitations. N/A values indicate metrics structurally inapplicable to that sector.
A53: © 2026 · Auto-generated 2026-07-09 10:08 · Source: SEC EDGAR via company_scanner.py

Sheet Industry_Benchmarks
A1: 📊 INDUSTRY BENCHMARK REFERENCE — GICS Sectors (2023-2024 Medians)
A3: Legend: | B3: 🟢 GOOD | C3: 📊 MEDIAN | D3: 🔴 POOR | E3: N/A = Metric not applicable for this sector | Source: Damodaran NYU, S&P Capital IQ, FactSet 2023-24
A4: Metric | B4: Info Tech | C4: Health Care | D4: Financials | E4: Cons. Disc. | F4: Cons. Staples | G4: Energy | H4: Industrials | I4: Materials | J4: Real Estate | K4: Utilities | L4: Comm. Svcs
A5: † For Financials sector, bank-specific metrics replace inapplicable ones: Gross Margin→Net Interest Margin | Current Ratio→Tier 1 Capital | ND/EBITDA→Loan-to-Deposit Ratio | Int.Coverage→Efficiency Ratio | DSO→NPL Ratio | DIO→Provision Coverage | CFO/NI→Payout Ratio ↓ = lower is better for that metric in the Financials column
A6: ─── PROFITABILITY ───
A7: EBIT Margin | B7: 🟢20% / 10% / 🔴5% | C7: 🟢18% / 10% / 🔴3% | D7: 🟢35% / 25% / 🔴10% | E7: 🟢15% / 8% / 🔴3% | F7: 🟢18% / 12% / 🔴6% | G7: 🟢20% / 12% / 🔴4% | H7: 🟢15% / 10% / 🔴5% | I7: 🟢18% / 12% / 🔴5% | J7: 🟢45% / 35% / 🔴20% | K7: 🟢25% / 18% / 🔴10% | L7: 🟢20% / 12% / 🔴4%
A8: Net Margin | B8: 🟢18% / 10% / 🔴3% | C8: 🟢15% / 8% / 🔴2% | D8: 🟢25% / 15% / 🔴5% | E8: 🟢10% / 6% / 🔴2% | F8: 🟢12% / 8% / 🔴4% | G8: 🟢15% / 8% / 🔴2% | H8: 🟢10% / 7% / 🔴3% | I8: 🟢12% / 8% / 🔴2% | J8: 🟢25% / 15% / 🔴5% | K8: 🟢15% / 10% / 🔴5% | L8: 🟢15% / 8% / 🔴2%
A9: Gross Margin (†Fin: NIM | †RE: NOI Margin | †Util: Op Margin) | B9: 🟢55% / 40% / 🔴25% | C9: 🟢60% / 45% / 🔴30% | D9: 🟢3% / 2% / 🔴2% | E9: 🟢45% / 35% / 🔴20% | F9: 🟢45% / 35% / 🔴25% | G9: 🟢35% / 25% / 🔴12% | H9: 🟢40% / 30% / 🔴18% | I9: 🟢35% / 25% / 🔴12% | J9: 🟢65% / 50% / 🔴35% | K9: 🟢45% / 35% / 🔴22% | L9: 🟢55% / 40% / 🔴25%
A10: ROE | B10: 🟢20% / 12% / 🔴5% | C10: 🟢18% / 12% / 🔴5% | D10: 🟢15% / 10% / 🔴5% | E10: 🟢20% / 15% / 🔴8% | F10: 🟢25% / 18% / 🔴10% | G10: 🟢15% / 10% / 🔴3% | H10: 🟢18% / 12% / 🔴6% | I10: 🟢15% / 10% / 🔴4% | J10: 🟢10% / 7% / 🔴3% | K10: 🟢12% / 9% / 🔴5% | L10: 🟢18% / 12% / 🔴5%
A11: ROA | B11: 🟢10% / 6% / 🔴2% | C11: 🟢8% / 5% / 🔴1% | D11: 🟢2% / 1% / 🔴0% | E11: 🟢10% / 6% / 🔴2% | F11: 🟢10% / 7% / 🔴3% | G11: 🟢8% / 5% / 🔴1% | H11: 🟢8% / 5% / 🔴2% | I11: 🟢7% / 4% / 🔴1% | J11: 🟢5% / 3% / 🔴1% | K11: 🟢4% / 3% / 🔴1% | L11: 🟢8% / 5% / 🔴1%
A12: ─── GROWTH ───
A13: Revenue Growth (Med) | B13: 🟢15% / 8% / 🔴0% | C13: 🟢10% / 6% / 🔴0% | D13: 🟢8% / 4% / 🔴0% | E13: 🟢8% / 4% / 🔴-2% | F13: 🟢5% / 2% / 🔴-2% | G13: 🟢10% / 2% / 🔴-10% | H13: 🟢8% / 4% / 🔴-2% | I13: 🟢6% / 2% / 🔴-5% | J13: 🟢6% / 3% / 🔴0% | K13: 🟢4% / 2% / 🔴0% | L13: 🟢10% / 5% / 🔴-2%
A14: FCF Margin | B14: 🟢15% / 8% / 🔴2% | C14: 🟢12% / 7% / 🔴1% | D14: 🟢20% / 12% / 🔴5% | E14: 🟢8% / 4% / 🔴1% | F14: 🟢8% / 5% / 🔴2% | G14: 🟢12% / 7% / 🔴1% | H14: 🟢8% / 5% / 🔴1% | I14: 🟢8% / 4% / 🔴1% | J14: 🟢30% / 20% / 🔴10% | K14: 🟢5% / 2% / 🔴-2% | L14: 🟢12% / 7% / 🔴1%
A15: ─── FINANCIAL HEALTH ───
A16: Current Ratio (†Fin: Tier 1 Capital | †RE: DSCR ↑) | B16: 🟢250% / 150% / 🔴100% | C16: 🟢200% / 150% / 🔴100% | D16: 🟢13% / 10% / 🔴8% | E16: 🟢180% / 130% / 🔴90% | F16: 🟢150% / 110% / 🔴80% | G16: 🟢150% / 110% / 🔴80% | H16: 🟢180% / 140% / 🔴100% | I16: 🟢180% / 140% / 🔴100% | J16: 🟢200% / 150% / 🔴125% | K16: 🟢100% / 80% / 🔴50% | L16: 🟢150% / 110% / 🔴70%
A17: Leverage (TL/TA) | B17: 🟢30% / 45% / 🔴65% | C17: 🟢35% / 50% / 🔴70% | D17: 🟢85% / 90% / 🔴95% | E17: 🟢40% / 55% / 🔴75% | F17: 🟢45% / 55% / 🔴70% | G17: 🟢40% / 55% / 🔴70% | H17: 🟢40% / 55% / 🔴70% | I17: 🟢40% / 55% / 🔴70% | J17: 🟢45% / 55% / 🔴70% | K17: 🟢55% / 65% / 🔴75% | L17: 🟢40% / 55% / 🔴70%
A18: Net Debt / EBITDA (†Financials: Loan-to-Deposit Ratio ↓) | B18: 🟢50% / 150% / 🔴300% | C18: 🟢100% / 250% / 🔴450% | D18: 🟢75% / 90% / 🔴110% | E18: 🟢100% / 250% / 🔴450% | F18: 🟢150% / 300% / 🔴500% | G18: 🟢50% / 150% / 🔴300% | H18: 🟢100% / 250% / 🔴400% | I18: 🟢100% / 250% / 🔴450% | J18: 🟢400% / 6.0x / 🔴9.0x | K18: 🟢300% / 500% / 🔴7.0x | L18: 🟢150% / 300% / 🔴500%
A19: Interest Coverage (†Financials: Efficiency Ratio ↓ better) | B19: 🟢15.0x / 8.0x / 🔴300% | C19: 🟢10.0x / 6.0x / 🔴250% | D19: 🟢50% / 60% / 🔴70% | E19: 🟢8.0x / 500% / 🔴200% | F19: 🟢8.0x / 500% / 🔴250% | G19: 🟢8.0x / 500% / 🔴200% | H19: 🟢8.0x / 500% / 🔴250% | I19: 🟢7.0x / 400% / 🔴200% | J19: 🟢400% / 250% / 🔴150% | K19: 🟢400% / 250% / 🔴150% | L19: 🟢8.0x / 400% / 🔴200%
A20: ─── QUALITY / WORKING CAPITAL ───
A21: CFO / Net Income (†Financials: Payout Ratio ↓ better) | B21: 🟢110% / 85% / 🔴60% | C21: 🟢110% / 85% / 🔴60% | D21: 🟢40% / 55% / 🔴70% | E21: 🟢110% / 85% / 🔴60% | F21: 🟢110% / 90% / 🔴70% | G21: 🟢130% / 100% / 🔴70% | H21: 🟢110% / 85% / 🔴65% | I21: 🟢110% / 85% / 🔴65% | J21: 🟢200% / 150% / 🔴100% | K21: 🟢150% / 120% / 🔴90% | L21: 🟢120% / 90% / 🔴65%
A22: DSO — days (†Fin: NPL Ratio | †RE: Occupancy Rate ↑) | B22: 🟢5000% / 6500% / 🔴9000% | C22: 🟢4500% / 6000% / 🔴9000% | D22: 🟢1% / 2% / 🔴4% | E22: 🟢2000% / 3500% / 🔴6000% | F22: 🟢2500% / 4000% / 🔴6000% | G22: 🟢3000% / 5000% / 🔴8000% | H22: 🟢4500% / 6000% / 🔴9000% | I22: 🟢4000% / 5500% / 🔴8000% | J22: 🟢97% / 92% / 🔴85% | K22: 🟢3000% / 4500% / 🔴6500% | L22: 🟢3500% / 5500% / 🔴8500%
A23: DIO — days (†Financials: Provision Coverage Ratio ↑) | B23: 🟢30.0x / 50.0x / 🔴80.0x | C23: 🟢60.0x / 90.0x / 🔴130.0x | D23: 🟢150% / 100% / 🔴80% | E23: 🟢40.0x / 70.0x / 🔴110.0x | F23: 🟢35.0x / 55.0x / 🔴80.0x | G23: 🟢20.0x / 40.0x / 🔴70.0x | H23: 🟢40.0x / 65.0x / 🔴100.0x | I23: 🟢50.0x / 75.0x / 🔴110.0x | J23: N/A | K23: N/A | L23: N/A
A24: ─── EARNINGS-QUALITY MODEL BASELINES ───
A25: Beneish M-Score Median | B25: -2.50 | C25: -2.60 | D25: -2.80 | E25: -2.40 | F25: -2.50 | G25: -2.40 | H25: -2.50 | I25: -2.40 | J25: -2.60 | K25: -2.70 | L25: -2.40
A26: Sloan Accrual Median | B26: 0.05 | C26: 0.03 | D26: 0.08 | E26: 0.04 | F26: 0.03 | G26: 0.05 | H26: 0.04 | I26: 0.05 | J26: -0.10 | K26: -0.05 | L26: 0.04
A27: ─── SECTOR NOTES ───
A28: Key considerations | B28: High gross margins expected. Watch for aggressive rev recognition in SaaS/cloud. | C28: Biotech/pharma often pre-revenue. Managed care has thin margins. Watch R&D capex. | D28: Z-Score/Current Ratio/DSO/DIO NOT applicable. Metrics shown are bank-equivalents: Gross Margin=NIM, Current Ratio=Tier1 Capital, ND/EBITDA=Loan-to-Deposit, Int.Coverage=Efficiency Ratio, DSO=NPL Ratio, DIO=Provision Coverage, CFO/NI=Payout Ratio. | E28: Retail has low margins. E-commerce growing. Watch inventory & same-store sales trends. | F28: Stable, low-growth sector. High dividend payers. Watch brand investment and pricing power. | G28: Highly cyclical — margins vary with commodity prices. EBITDA vs D&A critical for O&G. | H28: Diverse sector. Aerospace/defense has long cycles. Transportation sensitive to fuel costs. | I28: Commodity-linked. Capital intensive. High D&A. Inventory valuation method matters (LIFO/FIFO). | J28: Use FFO/AFFO not Net Income. Depreciation-heavy. Z-Score not applicable. Focus on occupancy & NOI. | K28: Regulated returns — stable but slow growth. Rate base investments drive capex. High debt normal. | L28: Mix of telcos (high capex, stable) and digital media (high growth, intangible-heavy).
A29: Source: Damodaran (NYU Stern), S&P Capital IQ, FactSet — FY2023/2024 median values. For reference only.

Sheet Inputs
A1: COMPANY HEALTH & RED-FLAG SCANNER — INPUT SHEET | D1: Prepared by: Your Name
A2: Company ID | B2: Ticker | C2: Company Name | D2: Sector | E2: Fiscal Year | F2: Total Assets Y0 | G2: Current Assets Y0 | H2: Current Liabilities Y0 | I2: Total Liabilities Y0 | J2: Retained Earnings Y0 | K2: EBIT Y0 | L2: Revenue Y0 | M2: Net Income Y0 | N2: CFO Y0 | O2: Gross Profit Y0 | P2: Long-term Debt Y0 | Q2: Equity Y0 | R2: SGA Y0 | S2: Depr&Amort Y0 | T2: Receivables Y0 | U2: PPE Y0 | V2: Interest Exp Y0 | W2: Total Assets Y1 | X2: Current Assets Y1 | Y2: Current Liabilities Y1 | Z2: Total Liabilities Y1 | AA2: EBIT Y1 | AB2: Revenue Y1 | AC2: Net Income Y1 | AD2: CFO Y1 | AE2: Gross Profit Y1 | AF2: Long-term Debt Y1 | AG2: Equity Y1 | AH2: Revenue Y2 | AI2: Total Assets Y2 | AJ2: EBT Y0 | AK2: EBT Y1 | AL2: Tax Expense Y0 | AM2: Tax Expense Y1 | AN2: CAPEX Y0 | AO2: CAPEX Y1 | AP2: Inventory Y0 | AQ2: Inventory Y1 | AR2: Goodwill Y0 | AS2: Intangibles Y0 | AT2: Short-term Debt Y0 | AU2: R&D Expense Y0 | AV2: Cash Y0 | AW2: Cash Y1 | AX2: Total Debt Y0 | AY2: Total Debt Y1 | AZ2: Net Debt Y0 | BA2: Free Cash Flow Y0 | BB2: Shares Outstanding Y0 | BC2: Shares Outstanding Y1 | BD2: Receivables Y1 | BE2: PPE Y1 | BF2: SGA Y1 | BG2: D&A Y1 | BH2: CFI Y0 | BI2: CFI Y1 | BJ2: Accounts Payable Y0 | BK2: Accounts Payable Y1 | BL2: Deferred Revenue Y0 | BM2: Deferred Revenue Y1 | BN2: Tax Payable Y0 | BO2: COGS Y0 | BP2: COGS Y1 | BQ2: DSO Y0 | BR2: DSO Y1 | BS2: DIO Y0 | BT2: DIO Y1 | BU2: DPO Y0 | BV2: DPO Y1 | BW2: Soft Assets % | BX2: Cash Collection Rate | BY2: Eff Tax Rate
A3: 1 | B3: AVY | C3: AVERY DENNISON CORPORATION | D3: Materials | E3: 2026 | F3: 8801.7 | G3: 2990.3 | H3: 2653.6 | I3: 8801.7 | J3: 5597.5 | K3: 925.1 | L3: 8855.5 | M3: 688 | N3: 881.4 | O3: 2546.3 | P3: 3199 | Q3: 2242.1 | R3: 1422.5 | S3: 328.2 | T3: 1503.9 | U3: 1540.2 | V3: 119 | W3: 8404.2 | X3: 3078.7 | Y3: 2862.6 | Z3: 8404.2 | AA3: 953.5 | AB3: 8755.7 | AC3: 704.9 | AD3: 938.8 | AE3: 2530.7 | AF3: 2550.8 | AG3: 2312.3 | AH3: 8755.7 | AI3: 8404.2 | AJ3: 925.1 | AK3: 953.5 | AL3: 237.1 | AM3: 248.6 | AN3: 169 | AO3: 208.8 | AP3: 975.8 | AQ3: 978.1 | AR3: 2272.5 | AS3: 652.7 | AT3: 522.9 | AU3: 136.6 | AV3: 202.8 | AW3: 329.1 | AX3: 3721.9 | AY3: 3143.1 | AZ3: 3519.1 | BA3: 712.4 | BB3: 76.9 | BC3: 79.8 | BD3: 1466.2 | BE3: 1477.7 | BF3: 1415.3 | BG3: 312.2 | BH3: -596 | BI3: -243.1 | BJ3: 1261.7 | BK3: 1340.7 | BL3: 16.2 | BM3: 15.5 | BN3: 86.1 | BO3: 6309.2 | BP3: 6225 | BQ3: 0 | BR3: 0 | BS3: 0 | BT3: 0 | BU3: 0 | BV3: 0 | BW3: 0 | BX3: 0 | BY3: 0
A4: 2 | B4: CHD | C4: CHURCH & DWIGHT CO., INC. | D4: Consumer Staples | E4: 2026 | F4: 8912.4 | G4: 1597 | H4: 1497.7 | I4: 4910.2 | J4: 6768.2 | K4: 1077.6 | L4: 6203.2 | M4: 736.8 | N4: 1215.4 | O4: 2774.8 | P4: 2205.1 | Q4: 4002.2 | R4: 988.3 | S4: 247.4 | T4: 593.4 | U4: 822.8 | V4: 95.2 | W4: 8883.1 | X4: 2240.6 | Y4: 1315.9 | Z4: 4522.3 | AA4: 807.1 | AB4: 6107.1 | AC4: 585.3 | AD4: 1156.2 | AE4: 2790.1 | AF4: 2204.6 | AG4: 4360.8 | AH4: 6107.1 | AI4: 8883.1 | AJ4: 956.9 | AK4: 756.3 | AL4: 220.1 | AM4: 171 | AN4: 122.4 | AO4: 179.8 | AP4: 534.8 | AQ4: 613.3 | AR4: 2627.5 | AS4: 0 | AT4: N/A | AU4: 145.6 | AV4: 409 | AW4: 964.1 | AX4: 2205.1 | AY4: 2208.5 | AZ4: 1796.1 | BA4: 1093 | BB4: 293.7 | BC4: 293.7 | BD4: 600.8 | BE4: 931.7 | BF4: 927.8 | BG4: 239.1 | BH4: -616.9 | BI4: -183.3 | BJ4: 732.4 | BK4: 705.1 | BL4: N/A | BM4: N/A | BN4: 3.4 | BO4: 3428.4 | BP4: 3317 | BQ4: 0 | BR4: 0 | BS4: 0 | BT4: 0 | BU4: 0 | BV4: 0 | BW4: 0 | BX4: 0 | BY4: 0
A5: 3 | B5: GWW | C5: W.W. GRAINGER, INC. | D5: Industrials | E5: 2026 | F5: 8962 | G5: 5484 | H5: 1940 | I5: 8962 | J5: 14958 | K5: 2495 | L5: 17942 | M5: 1706 | N5: 2015 | O5: 7009 | P5: 2488 | Q5: 3736 | R5: 4514 | S5: 254 | T5: 2329 | U5: 2268 | V5: 88 | W5: 8829 | X5: 5737 | Y5: 2305 | Z5: 8829 | AA5: 2637 | AB5: 17168 | AC5: 1909 | AD5: 2111 | AE5: 6758 | AF5: 2778 | AG5: 3358 | AH5: 17168 | AI5: 8829 | AJ5: 2430 | AK5: 2584 | AL5: 622 | AM5: 595 | AN5: 684 | AO5: 541 | AP5: 2394 | AQ5: 2306 | AR5: 360 | AS5: 246 | AT5: N/A | AU5: N/A | AV5: 585 | AW5: 1036 | AX5: 2488 | AY5: 2833 | AZ5: 1903 | BA5: 1331 | BB5: 109.7 | BC5: 109.7 | BD5: 2232 | BE5: 1927 | BF5: 4121 | BG5: 237 | BH5: -645 | BI5: -520 | BJ5: N/A | BK5: N/A | BL5: N/A | BM5: N/A | BN5: 49 | BO5: 10933 | BP5: 10410 | BQ5: 0 | BR5: 0 | BS5: 0 | BT5: 0 | BU5: 0 | BV5: N/A | BW5: 0 | BX5: 0 | BY5: 0
A6: 4 | B6: SO | C6: SOUTHERN CO | D6: Utilities | E6: 2026 | F6: 155720 | G6: 10917 | H6: 16888 | I6: 116853 | J6: 14856 | K6: 7285 | L6: 29553 | M6: 4341 | N6: 9802 | O6: N/A | P6: N/A | Q6: 36016 | R6: N/A | S6: 32 | T6: 3139 | U6: 99844 | V6: N/A | W6: 145180 | X6: 10694 | Y6: 15993 | Z6: 108506 | AA6: 7068 | AB6: 26724 | AC6: 4401 | AD6: 9788 | AE6: N/A | AF6: N/A | AG6: 33208 | AH6: 26724 | AI6: 145180 | AJ6: 4999 | AK6: 5229 | AL6: 828 | AM6: 969 | AN6: 12737 | AO6: 8955 | AP6: N/A | AQ6: N/A | AR6: 5161 | AS6: 225 | AT6: 722 | AU6: N/A | AV6: 1639 | AW6: 1070 | AX6: 722 | AY6: N/A | AZ6: -917 | BA6: -2935 | BB6: 1100 | BC6: 1100 | BD6: 3048 | BE6: 94570 | BF6: N/A | BG6: 35 | BH6: -13959 | BI6: -9400 | BJ6: 3710 | BK6: 3701 | BL6: 213 | BM6: 140 | BN6: 22 | BO6: N/A | BP6: N/A | BQ6: 0 | BR6: 0 | BS6: N/A | BT6: N/A | BU6: N/A | BV6: N/A | BW6: 0 | BX6: 0 | BY6: 0
A7: 5 | B7: VICI | C7: VICI Properties Inc. | D7: Real Estate | E7: 2026 | F7: 46724.2 | G7: N/A | H7: N/A | I7: 18501.6 | J7: 2767.1 | K7: 321 | L7: 4006.1 | M7: 2775.5 | N7: 2510 | O7: 3979.4 | P7: 16773.2 | Q7: 27797.6 | R7: 65.1 | S7: 3.6 | T7: N/A | U7: 68 | V7: 818.1 | W7: 45368.9 | X7: N/A | Y7: N/A | Z7: 18417.1 | AA7: 842.5 | AB7: 3849.2 | AC7: 2678.8 | AD7: 2381.5 | AE7: 3822.3 | AF7: 16732.9 | AG7: 26538 | AH7: 3849.2 | AI7: 45368.9 | AJ7: 2821 | AK7: 2730.9 | AL7: 2.4 | AM7: 9.7 | AN7: 2.7 | AO7: 0.9 | AP7: N/A | AQ7: N/A | AR7: N/A | AS7: N/A | AT7: N/A | AU7: N/A | AV7: 563.5 | AW7: 524.6 | AX7: 16773.2 | AY7: 16732.9 | AZ7: 16209.8 | BA7: 2507.3 | BB7: 1068.8 | BC7: 1056.4 | BD7: N/A | BE7: 70.3 | BF7: 69.1 | BG7: 4.1 | BH7: -904.8 | BI7: -922.8 | BJ7: N/A | BK7: N/A | BL7: 68.1 | BM7: N/A | BN7: N/A | BO7: 26.7 | BP7: 26.9 | BQ7: N/A | BR7: N/A | BS7: N/A | BT7: N/A | BU7: N/A | BV7: N/A | BW7: 0 | BX7: 0 | BY7: 0
A8: 6 | B8: MPWR | C8: MONOLITHIC POWER SYSTEMS INC | D8: Information Technology | E8: 2026 | F8: 4194.2 | G8: 2183.8 | H8: 369.4 | I8: 662.7 | J8: 2609.7 | K8: 728.6 | L8: 333.1 | M8: 621.5 | N8: 838.2 | O8: 1539.7 | P8: N/A | Q8: 3531.5 | R8: 428.8 | S8: 52.5 | T8: 255.6 | U8: 627.7 | V8: N/A | W8: 4107.2 | X8: 2112.7 | Y8: 442.8 | Z8: 729.9 | AA8: 528.7 | AB8: 282.5 | AC8: 449.8 | AD8: 788.4 | AE8: 1125.5 | AF8: N/A | AG8: 3377.3 | AH8: 282.5 | AI8: 3872.3 | AJ8: 766.2 | AK8: 556.4 | AL8: 144.7 | AM8: 106.6 | AN8: 172 | AO8: 146.1 | AP8: 564.6 | AQ8: 505.7 | AR8: 25.9 | AS8: 0.1 | AT8: N/A | AU8: 44.5 | AV8: 1099.3 | AW8: 1081.3 | AX8: N/A | AY8: N/A | AZ8: N/A | BA8: 666.2 | BB8: 48.7 | BC8: 47.9 | BD8: 241.6 | BE8: 597.3 | BF8: 310.1 | BG8: 36.4 | BH8: -157.3 | BI8: 223 | BJ8: 138.3 | BK8: 141.7 | BL8: 1.8 | BM8: 1.8 | BN8: 8.1 | BO8: 1250.7 | BP8: 913.8 | BQ8: 0 | BR8: 0 | BS8: 0 | BT8: 0 | BU8: 0 | BV8: 0 | BW8: 0 | BX8: 0 | BY8: 0
A9: 7 | B9: EWBC | C9: EAST WEST BANCORP INC | D9: Financials | E9: 2026 | F9: 80435 | G9: N/A | H9: N/A | I9: 71535.8 | J9: 8301.5 | K9: 1725.5 | L9: 55.3 | M9: 1325.2 | N9: 1501.7 | O9: N/A | P9: 146.8 | Q9: 8899.2 | R9: N/A | S9: 213.2 | T9: N/A | U9: 82.3 | V9: 1381.6 | W9: 75976.5 | X9: N/A | Y9: N/A | Z9: 68253.4 | AA9: 1481.9 | AB9: 53.6 | AC9: 1165.6 | AD9: 1411.7 | AE9: N/A | AF9: 146.8 | AG9: 7723.1 | AH9: 53 | AI9: 75976.5 | AJ9: 1725.5 | AK9: 1481.9 | AL9: 400.3 | AM9: 316.3 | AN9: 6 | AO9: 2.7 | AP9: N/A | AQ9: N/A | AR9: 465.7 | AS9: 28 | AT9: 28.7 | AU9: N/A | AV9: 4188.1 | AW9: 5250.7 | AX9: 175.5 | AY9: 204.5 | AZ9: -4012.6 | BA9: 1495.7 | BB9: 143.6 | BC9: 137.6 | BD9: N/A | BE9: 82.2 | BF9: N/A | BG9: 198.4 | BH9: -5476.5 | BI9: -6295.2 | BJ9: N/A | BK9: N/A | BL9: N/A | BM9: N/A | BN9: N/A | BO9: N/A | BP9: N/A | BQ9: N/A | BR9: N/A | BS9: N/A | BT9: N/A | BU9: N/A | BV9: N/A | BW9: 0 | BX9: 0 | BY9: 0
A10: 8 | B10: BEN | C10: FRANKLIN RESOURCES, INC. | D10: Financials | E10: 2026 | F10: 32368.3 | G10: 7616.8 | H10: 1312.1 | I10: 18179.5 | J10: 11516 | K10: 604.1 | L10: 5774.5 | M10: 524.9 | N10: 1066.1 | O10: -2392.1 | P10: 2362 | Q10: 12077.8 | R10: 774.5 | S10: 141.4 | T10: 772.5 | U10: 949.1 | V10: 94.9 | W10: 32464.5 | X10: 6362.8 | Y10: 1006.6 | Z10: 17899.7 | AA10: 407.6 | AB10: 6319.1 | AC10: 464.8 | AD10: 971.3 | AE10: -1751.3 | AF10: 2780.3 | AG10: 12508.1 | AH10: 6319.1 | AI10: 32464.5 | AJ10: 786.8 | AK10: 823.2 | AL10: 237.9 | AM10: 215.3 | AN10: 154.5 | AO10: 177.1 | AP10: N/A | AQ10: N/A | AR10: 6206 | AS10: 765.7 | AT10: 84.5 | AU10: N/A | AV10: 4647.2 | AW10: 3957.5 | AX10: 2446.5 | AY10: 2810.3 | AZ10: -2200.7 | BA10: 911.6 | BB10: 521 | BC10: 523.6 | BD10: 684.2 | BE10: 946.4 | BF10: 703.3 | BG10: 129.9 | BH10: -2342.7 | BI10: -2423.7 | BJ10: 328.3 | BK10: 207.4 | BL10: N/A | BM10: N/A | BN10: 128.8 | BO10: 8166.6 | BP10: 8070.4 | BQ10: 0 | BR10: 0 | BS10: N/A | BT10: N/A | BU10: 0 | BV10: 0 | BW10: 0 | BX10: 0 | BY10: 0
A11: 9 | B11: NVDA | C11: NVIDIA CORP | D11: Information Technology | E11: 2026 | F11: 206803 | G11: 125605 | H11: 32163 | I11: 49510 | J11: 146973 | K11: 130387 | L11: 215938 | M11: 120067 | N11: 102718 | O11: 153463 | P11: 8468 | Q11: 157293 | R11: 4579 | S11: 1098 | T11: 38466 | U11: 10383 | V11: 257 | W11: 111601 | X11: 80126 | Y11: 18047 | Z11: 32274 | AA11: 81453 | AB11: 130497 | AC11: 72880 | AD11: 64089 | AE11: 97858 | AF11: 8463 | AG11: 79327 | AH11: 130497 | AI11: 111601 | AJ11: 141450 | AK11: 84026 | AL11: 21383 | AM11: 11146 | AN11: 138.7 | AO11: 97.9 | AP11: 21403 | AQ11: 10080 | AR11: 20832 | AS11: 3306 | AT11: 999 | AU11: 18497 | AV11: 10605 | AW11: 8589 | AX11: 9467 | AY11: 8463 | AZ11: -1138 | BA11: 102579.3 | BB11: 24304 | BC11: 24477 | BD11: 23065 | BE11: 6283 | BF11: 3491 | BG11: 381 | BH11: -52228 | BI11: -20421 | BJ11: 9812 | BK11: 6310 | BL11: 53 | BM11: 85 | BN11: 2669 | BO11: 6279 | BP11: 4150 | BQ11: 0 | BR11: 0 | BS11: 0 | BT11: 0 | BU11: 0 | BV11: 0 | BW11: 0 | BX11: 0 | BY11: 0
A12: 10 | B12: KRYS | C12: Krystal Biotech, Inc. | D12: Health Care | E12: 2026 | F12: 1333.8 | G12: 1024.6 | H12: 102.9 | I12: 114.2 | J12: 24.2 | K12: 161.3 | L12: 389.1 | M12: 204.8 | N12: 200.9 | O12: 161.3 | P12: 4.3 | Q12: 1219.6 | R12: 146.7 | S12: 4.1 | T12: 127.4 | U12: 150.8 | V12: N/A | W12: 1055.8 | X12: 742 | Y12: 102 | Z12: 109.5 | AA12: 65.7 | AB12: 290.5 | AC12: 89.2 | AD12: 123.4 | AE12: 65.7 | AF12: N/A | AG12: 946.4 | AH12: 290.5 | AI12: 1055.8 | AJ12: 189.5 | AK12: 95.4 | AL12: -15.4 | AM12: 6.2 | AN12: 12 | AO12: 4.2 | AP12: 40.5 | AQ12: 26.5 | AR12: N/A | AS12: N/A | AT12: N/A | AU12: 58 | AV12: 496.3 | AW12: 344.9 | AX12: 4.3 | AY12: N/A | AZ12: -492.1 | BA12: 188.9 | BB12: 29.2 | BC12: 28.8 | BD12: 104.7 | BE12: 155.2 | BF12: 113.7 | BG12: 2.8 | BH12: -58.4 | BI12: -163.4 | BJ12: 3.2 | BK12: 5 | BL12: N/A | BM12: N/A | BN12: N/A | BO12: 227.8 | BP12: 224.8 | BQ12: 0 | BR12: 0 | BS12: 0 | BT12: 0 | BU12: 0 | BV12: 0 | BW12: 0 | BX12: 0 | BY12: 0
A13: 11 | B13: APTV | C13: APTIV PLC | D13: Consumer Discretionary | E13: 2026 | F13: 23413 | G13: 8745 | H13: 5037 | I13: 13914 | J13: 6227 | K13: 1184 | L13: 20398 | M13: 165 | N13: 2185 | O13: 963 | P13: 7653 | Q13: 9207 | R13: 1673 | S13: 991 | T13: 3477 | U13: 3774 | V13: 361 | W13: 23458 | X13: 7826 | Y13: 5131 | Z13: 14373 | AA13: 425 | AB13: 5153 | AC13: 138 | AD13: 2446 | AE13: 962 | AF13: 8465 | AG13: 8796 | AH13: 19713 | AI13: 23458 | AJ13: 919 | AK13: 2151 | AL13: 700 | AM13: 223 | AN13: 844 | AO13: 611 | AP13: 2561 | AQ13: 2320 | AR13: 4596 | AS13: 1838 | AT13: 81 | AU13: 1129 | AV13: 1851 | AW13: 1573 | AX13: 7734 | AY13: 8974 | AZ13: 5883 | BA13: 1341 | BB13: 212.7 | BC13: 235 | BD13: 3261 | BE13: 3698 | BF13: 1465 | BG13: 964 | BH13: -498 | BI13: -507 | BJ13: 3157 | BK13: 2870 | BL13: 84 | BM13: 111 | BN13: 240 | BO13: 16500 | BP13: 4190 | BQ13: 0 | BR13: 0 | BS13: 0 | BT13: 0 | BU13: 0 | BV13: 0 | BW13: 0 | BX13: 0 | BY13: 0
A14: 12 | B14: ZBRA | C14: ZEBRA TECHNOLOGIES CORPORATION | D14: Information Technology | E14: 2026 | F14: 8502 | G14: 1796 | H14: 1852 | I14: 4914 | J14: 5279 | K14: 700 | L14: 5396 | M14: 419 | N14: 917 | O14: 2593 | P14: 266 | Q14: 3588 | R14: 433 | S14: 185 | T14: 801 | U14: 353 | V14: 5 | W14: 7968 | X14: 2440 | Y14: 1704 | Z14: 4382 | AA14: 742 | AB14: 4981 | AC14: 528 | AD14: 1013 | AE14: 2413 | AF14: 2176 | AG14: 3586 | AH14: 4981 | AI14: 7968 | AJ14: 560 | AK14: 635 | AL14: 141 | AM14: 107 | AN14: 86 | AO14: 59 | AP14: 729 | AQ14: 693 | AR14: 4727 | AS14: 809 | AT14: 141 | AU14: 593 | AV14: 125 | AW14: 901 | AX14: 407 | AY14: 2176 | AZ14: 282 | BA14: 831 | BB14: 51.7 | BC14: 50.3 | BD14: 692 | BE14: 305 | BF14: 381 | BG14: 172 | BH14: -1455 | BI14: -57 | BJ14: 695 | BK14: 633 | BL14: 210 | BM14: 184 | BN14: 12 | BO14: 2803 | BP14: 2568 | BQ14: 0 | BR14: 0 | BS14: 0 | BT14: 0 | BU14: 0 | BV14: 0 | BW14: 0 | BX14: 0 | BY14: 0
A15: 13 | B15: WFC | C15: WELLS FARGO & COMPANY/MN | D15: Financials | E15: 2026 | F15: 2148631 | G15: N/A | H15: N/A | I15: 1965593 | J15: 228873 | K15: 25199 | L15: 85063 | M15: 21338 | N15: -19001 | O15: N/A | P15: 174712 | Q15: 181117 | R15: N/A | S15: 1700 | T15: 19651 | U15: 9309 | V15: 32743 | W15: 1929845 | X15: N/A | Y15: N/A | Z15: 1748779 | AA15: 23364 | AB15: 86408 | AC15: 19722 | AD15: 3035 | AE15: N/A | AF15: 173078 | AG15: 179120 | AH15: 86408 | AI15: 1929845 | AJ15: 25199 | AK15: 23364 | AL15: 3841 | AM15: 3399 | AN15: N/A | AO15: N/A | AP15: N/A | AQ15: N/A | AR15: 24967 | AS15: 1322 | AT15: 18323 | AU15: N/A | AV15: N/A | AW15: N/A | AX15: 193035 | AY15: 281884 | AZ15: 193035 | BA15: N/A | BB15: 3092.6 | BC15: 3288.9 | BD15: 19608 | BE15: 8920 | BF15: N/A | BG15: 1400 | BH15: -187895 | BI15: -15651 | BJ15: N/A | BK15: N/A | BL15: N/A | BM15: N/A | BN15: N/A | BO15: N/A | BP15: N/A | BQ15: 0 | BR15: 0 | BS15: N/A | BT15: N/A | BU15: N/A | BV15: N/A | BW15: 0 | BX15: 0 | BY15: 0
A16: 14 | B16: EXPD | C16: EXPEDITORS INTERNATIONAL OF WASHINGTON, INC. | D16: Industrials | E16: 2026 | F16: 4893.6 | G16: 3755.6 | H16: 2072.8 | I16: 4893.6 | J16: 2538.5 | K16: 1052.5 | L16: 6920.9 | M16: 810.3 | N16: 1006.5 | O16: 1824.1 | P16: N/A | Q16: 2355.6 | R16: 40.1 | S16: 39.9 | T16: 2021.9 | U16: 462.1 | V16: 4.8 | W16: 4754.5 | X16: 3659.8 | Y16: 2066.5 | Z16: 4754.5 | AA16: 1041.3 | AB16: 1901.4 | AC16: 810.1 | AD16: 723.4 | AE16: 458.7 | AF16: N/A | AG16: 2223 | AH16: 1802.2 | AI16: 4754.5 | AJ16: 1094.1 | AK16: 1094.8 | AL16: 282 | AM16: 283.2 | AN16: 53.1 | AO16: 40.5 | AP16: N/A | AQ16: N/A | AR16: 7.9 | AS16: 2.6 | AT16: N/A | AU16: N/A | AV16: 1314.3 | AW16: 1148.3 | AX16: N/A | AY16: N/A | AZ16: N/A | BA16: 953.4 | BB16: 133.9 | BC16: 138 | BD16: 1997.8 | BE16: 449.4 | BF16: 33.3 | BG16: 36.8 | BH16: -44.7 | BI16: -40.5 | BJ16: 1123.4 | BK16: 1036.7 | BL16: 358.4 | BM16: 441.9 | BN16: 32 | BO16: N/A | BP16: N/A | BQ16: 0 | BR16: 0 | BS16: N/A | BT16: N/A | BU16: 0 | BV16: 0 | BW16: 0 | BX16: 0 | BY16: 0
A17: 15 | B17: CELH | C17: CELSIUS HOLDINGS, INC. | D17: Consumer Staples | E17: 2026 | F17: 5119.6 | G17: 1811.2 | H17: 1078.7 | I17: 2178.2 | J17: 175.9 | K17: 141.1 | L17: 1318 | M17: 108 | N17: 359.4 | O17: 1267.3 | P17: 676.9 | Q17: 1181.5 | R17: 798.8 | S17: 29.5 | T17: 755.5 | U17: 87.9 | V17: 0.5 | W17: 1766.9 | X17: 1324.6 | Y17: 365.5 | Z17: 542.5 | AA17: 155.7 | AB17: 653.6 | AC17: 145.1 | AD17: 262.9 | AE17: 680.2 | AF17: N/A | AG17: 399.9 | AH17: 653.6 | AI17: 1766.9 | AJ17: 125 | AK17: 195.1 | AL17: 17 | AM17: 50 | AN17: 36.1 | AO17: 23.4 | AP17: 337.7 | AQ17: 131.2 | AR17: 917.6 | AS17: 111.9 | AT17: 7 | AU17: 2.4 | AV17: 398.9 | AW17: 890.2 | AX17: 683.9 | AY17: N/A | AZ17: 285.1 | BA17: 323.4 | BB17: 256.9 | BC17: 235 | BD17: 270.3 | BE17: 55.6 | BF17: 524.5 | BG17: 7.3 | BH17: -1295.7 | BI17: -101.7 | BJ17: 137.9 | BK17: 41.3 | BL17: 9.5 | BM17: 9.7 | BN17: 49.6 | BO17: 1247.9 | BP17: 675.4 | BQ17: 0 | BR17: 0 | BS17: 0 | BT17: 0 | BU17: 0 | BV17: 0 | BW17: 0 | BX17: 0 | BY17: 0
A18: 16 | B18: MKSI | C18: MKS INC | D18: Information Technology | E18: 2026 | F18: 8796 | G18: 2510 | H18: 927 | I18: 6077 | J18: 711 | K18: 528 | L18: 3931 | M18: 295 | N18: 645 | O18: 1837 | P18: 4150 | Q18: 2719 | R18: 724 | S18: 344 | T18: 651 | U18: 810 | V18: 212 | W18: 8590 | X18: 2474 | Y18: 775 | Z18: 6268 | AA18: 498 | AB18: 3586 | AC18: 190 | AD18: 528 | AE18: 1708 | AF18: 4488 | AG18: 2322 | AH18: 3586 | AI18: 8590 | AJ18: 304 | AK18: 180 | AL18: 9 | AM18: -10 | AN18: 148 | AO18: 118 | AP18: 921 | AQ18: 893 | AR18: 2574 | AS18: 2140 | AT18: 51 | AU18: 299 | AV18: 418 | AW18: 420 | AX18: 4201 | AY18: 4538 | AZ18: 3783 | BA18: 497 | BB18: 67.2 | BC18: 67.4 | BD18: 615 | BE18: 771 | BF18: 674 | BG18: 348 | BH18: -145 | BI18: -117 | BJ18: 407 | BK18: 341 | BL18: 12.8 | BM18: 14.5 | BN18: 51 | BO18: 2000 | BP18: 1569.4 | BQ18: 0 | BR18: 0 | BS18: 0 | BT18: 0 | BU18: 0 | BV18: 0 | BW18: 0 | BX18: 0 | BY18: 0
A19: 17 | B19: ACAD | C19: ACADIA PHARMACEUTICALS INC | D19: Health Care | E19: 2026 | F19: 1564.2 | G19: 1062.1 | H19: 277.1 | I19: 336.8 | J19: -1813.4 | K19: 104.8 | L19: 726.4 | M19: 391 | N19: 109.8 | O19: 684.8 | P19: N/A | Q19: 1227.4 | R19: 548.9 | S19: 0.2 | T19: 121.5 | U19: 7.5 | V19: 0 | W19: 1187.8 | X19: 938.3 | Y19: 394.9 | Z19: 455 | AA19: 230.8 | AB19: 231 | AC19: 226.5 | AD19: 157.7 | AE19: 213.2 | AF19: N/A | AG19: 732.8 | AH19: 211.7 | AI19: 1187.8 | AJ19: 138.9 | AK19: 258.1 | AL19: -252.1 | AM19: 31.6 | AN19: 4.7 | AO19: 0.5 | AP19: 111.4 | AQ19: 91.7 | AR19: N/A | AS19: 108.9 | AT19: 0 | AU19: 328.8 | AV19: 177.7 | AW19: 319.6 | AX19: 0 | AY19: N/A | AZ19: -177.7 | BA19: 105.1 | BB19: 170.3 | BC19: 166.7 | BD19: 98.7 | BE19: 4.2 | BF19: 488.4 | BG19: 0.1 | BH19: -302.6 | BI19: -30.5 | BJ19: 10.9 | BK19: 16.2 | BL19: 2.6 | BM19: 2.6 | BN19: N/A | BO19: 89 | BP19: 81.8 | BQ19: 0 | BR19: 0 | BS19: 0 | BT19: 0 | BU19: 0 | BV19: 0 | BW19: 0 | BX19: 0 | BY19: 0
A20: 18 | B20: NEM | C20: NEWMONT CORPORATION | D20: Materials | E20: 2026 | F20: 57121 | G20: 13066 | H20: 5712 | I20: 23079 | J20: 3431 | K20: 11342 | L20: 6711 | M20: 7085 | N20: 10334 | O20: 780 | P20: 5115 | Q20: 33867 | R20: 382 | S20: 1229 | T20: 1067 | U20: 25276 | V20: 249 | W20: 56349 | X20: 12275 | Y20: 7543 | Z20: 26240 | AA20: 4577 | AB20: 7729 | AC20: 3348 | AD20: 6363 | AE20: 711 | AF20: 8476 | AG20: 29928 | AH20: 6085 | AI20: 56349 | AJ20: 11342 | AK20: 4577 | AL20: 4596 | AM20: 1397 | AN20: 3035 | AO20: 3402 | AP20: 700 | AQ20: 717 | AR20: 2658 | AS20: 94 | AT20: N/A | AU20: 166 | AV20: 7647 | AW20: 3619 | AX20: 5115 | AY20: 8476 | AZ20: -2532 | BA20: 7299 | BB20: 1089 | BC20: 1127 | BD20: 1056 | BE20: 12258 | BF20: 442 | BG20: 1362 | BH20: 606 | BI20: -2702 | BJ20: 816 | BK20: 843 | BL20: N/A | BM20: N/A | BN20: 1188 | BO20: N/A | BP20: N/A | BQ20: 0 | BR20: 0 | BS20: 0 | BT20: 0 | BU20: 0 | BV20: 0 | BW20: 0 | BX20: 0 | BY20: 0
A21: 19 | B21: NFLX | C21: Netflix, Inc. | D21: Communication Services | E21: 2026 | F21: 55597 | G21: 13020.2 | H21: 10980.9 | I21: 28981.5 | J21: 42282.1 | K21: 13326.6 | L21: 45183 | M21: 10981.2 | N21: 10149.3 | O21: 2479.3 | P21: 21857.1 | Q21: 26615.5 | R21: 1888.4 | S21: 45.5 | T21: N/A | U21: 2004.3 | V21: 699.8 | W21: 53630.4 | X21: 13100.4 | Y21: 10755.4 | Z21: 28886.8 | AA21: 10417.6 | AB21: 39001 | AC21: 8711.6 | AD21: 7361.4 | AE21: 2567.9 | AF21: 20723.4 | AG21: 24743.6 | AH21: 39001 | AI21: 53630.4 | AJ21: 12722.6 | AK21: 9965.7 | AL21: 1741.4 | AM21: 1254 | AN21: 688.2 | AO21: 439.5 | AP21: N/A | AQ21: N/A | AR21: N/A | AS21: 32778.4 | AT21: 998.9 | AU21: 3391.4 | AV21: 9033.7 | AW21: 7804.7 | AX21: 22856 | AY21: 22507.9 | AZ21: 13822.3 | BA21: 9461.1 | BB21: 4222.2 | BC21: 427.8 | BD21: N/A | BE21: 1593.8 | BF21: 1702 | BG21: 43.7 | BH21: 1041.7 | BI21: -2181.8 | BJ21: 900.6 | BK21: 899.9 | BL21: 618.6 | BM21: 618.6 | BN21: N/A | BO21: 23275.3 | BP21: 21038.5 | BQ21: N/A | BR21: N/A | BS21: N/A | BT21: N/A | BU21: 0 | BV21: 0 | BW21: 0 | BX21: 0 | BY21: 0
A22: 20 | B22: BWA | C22: BORGWARNER INC | D22: Consumer Discretionary | E22: 2026 | F22: 13769 | G22: 6795 | H22: 3282 | I22: 8155 | J22: 6570 | K22: 536 | L22: 14316 | M22: 277 | N22: 1569 | O22: 2674 | P22: 1926 | Q22: 5442 | R22: 1304 | S22: 568 | T22: 2962 | U22: 2925 | V22: 99 | W22: 13993 | X22: 6521 | Y22: 3646 | Z22: 8287 | AA22: 546 | AB22: 14086 | AC22: 338 | AD22: 1306 | AE22: 2648 | AF22: 2080.5 | AG22: 5532 | AH22: 14086 | AI22: 13993 | AJ22: 524 | AK22: 539 | AL22: 189 | AM22: 111 | AN22: 469 | AO22: 671 | AP22: 1207 | AQ22: 1251 | AR22: 2055 | AS22: 390 | AT22: 122.4 | AU22: 710 | AV22: 1841 | AW22: 1650 | AX22: 2048.4 | AY22: 2144.5 | AZ22: 207.4 | BA22: 1100 | BB22: 207.1 | BC22: 218.7 | BD22: 2843 | BE22: 2903.8 | BF22: 1350 | BG22: 439 | BH22: -1418 | BI22: -1395 | BJ22: 2684 | BK22: 2276 | BL22: 52.4 | BM22: 52.4 | BN22: 113 | BO22: 11642 | BP22: 11438 | BQ22: 0 | BR22: 0 | BS22: 0 | BT22: 0 | BU22: 0 | BV22: 0 | BW22: 0 | BX22: 0 | BY22: 0
A23: 21 | B23: CCL | C23: Carnival Corporation Ltd. | D23: Consumer Discretionary | E23: 2026 | F23: 51687 | G23: 4219 | H23: 13092 | I23: 51687 | J23: 4817 | K23: 4483 | L23: 18881 | M23: 2760 | N23: 6218 | O23: 3243 | P23: 27383 | Q23: 12284 | R23: 3402 | S23: 2790 | T23: 678 | U23: 43494 | V23: 2066 | W23: 49057 | X23: 3378 | Y23: 11617 | Z23: 49057 | AA23: 3574 | AB23: 17510 | AC23: 1916 | AD23: 5923 | AE23: 3193 | AF23: 28213 | AG23: 9251 | AH23: 17510 | AI23: 49057 | AJ23: 2772 | AK23: 1915 | AL23: 12 | AM23: -1 | AN23: 3611 | AO23: 4626 | AP23: 505 | AQ23: 507 | AR23: 579 | AS23: 1177 | AT23: N/A | AU23: N/A | AV23: 1928 | AW23: 1210 | AX23: 27383 | AY23: 28413 | AZ23: 25455 | BA23: 2607 | BB23: 646 | BC23: 644 | BD23: 590 | BE23: 41795 | BF23: 3252 | BG23: 2557 | BH23: -3321 | BI23: -4535 | BJ23: 1245 | BK23: 1133 | BL23: 6831 | BM23: 6425 | BN23: N/A | BO23: 15638 | BP23: 14317 | BQ23: 0 | BR23: 0 | BS23: 0 | BT23: 0 | BU23: 0 | BV23: 0 | BW23: 0 | BX23: 0 | BY23: 0
A24: 22 | B24: BIO | C24: Bio-Rad Laboratories, Inc. | D24: Health Care | E24: 2026 | F24: 10576.5 | G24: 2906.2 | H24: 517 | I24: 3122.9 | J24: 8176.3 | K24: 47.2 | L24: 2583.2 | M24: 759.9 | N24: 532.2 | O24: 1339.9 | P24: 1203 | Q24: 7453.6 | R24: 844.3 | S24: 165.4 | T24: 460.6 | U24: 539.9 | V24: 49 | W24: 9364.1 | X24: 3030.3 | Y24: 467.8 | Z24: 2794.8 | AA24: 269 | AB24: 2566.5 | AC24: -1844.2 | AD24: 455.2 | AE24: 1378.9 | AF24: 1210.4 | AG24: 6569.3 | AH24: 2566.5 | AI24: 9364.1 | AJ24: 995.5 | AK24: -2342.5 | AL24: 235.6 | AM24: -498.3 | AN24: 157.6 | AO24: 165.6 | AP24: 740.7 | AQ24: 760 | AR24: 579.8 | AS24: 174.3 | AT24: 0.2 | AU24: 275.6 | AV24: 529.8 | AW24: 488.1 | AX24: 1203.2 | AY24: 1210.4 | AZ24: 673.4 | BA24: 374.6 | BB24: N/A | BC24: N/A | BD24: 452.5 | BE24: 528.1 | BF24: 814 | BG24: 151.6 | BH24: -189.7 | BI24: -160.2 | BJ24: 129 | BK24: 122.3 | BL24: 48.9 | BM24: 47.8 | BN24: 36.6 | BO24: 1243.3 | BP24: 1187.6 | BQ24: 0 | BR24: 0 | BS24: 0 | BT24: 0 | BU24: 0 | BV24: 0 | BW24: 0 | BX24: 0 | BY24: 0
A25: 23 | B25: GEHC | C25: GE HEALTHCARE TECHNOLOGIES INC. | D25: Health Care | E25: 2026 | F25: 36906 | G25: 12501 | H25: 9105 | I25: 26307 | J25: 5281 | K25: 2763 | L25: 20625 | M25: 2084 | N25: N/A | O25: 8248 | P25: 10003 | Q25: 10379 | R25: 4225 | S25: 287 | T25: N/A | U25: 2144 | V25: N/A | W25: 33089 | X25: 9901 | Y25: 9553 | Z25: 24437 | AA25: 2625 | AB25: 19672 | AC25: 1993 | AD25: N/A | AE25: 8205 | AF25: 8951 | AG25: 8446 | AH25: 19672 | AI25: 33089 | AJ25: 2768 | AK25: 2581 | AL25: 614 | AM25: 531 | AN25: 482 | AO25: 401 | AP25: 2234 | AQ25: 1939 | AR25: 13489 | AS25: 1055 | AT25: 508 | AU25: 1260 | AV25: 4492 | AW25: 2874 | AX25: 10511 | AY25: 10453 | AZ25: 6019 | BA25: N/A | BB25: 455.3 | BC25: 454 | BD25: N/A | BE25: 2001 | BF25: 4269 | BG25: 268 | BH25: -1047 | BI25: -914 | BJ25: 3250 | BK25: 3022 | BL25: 2095 | BM25: 1943 | BN25: N/A | BO25: 5485 | BP25: 5580 | BQ25: N/A | BR25: N/A | BS25: 0 | BT25: 0 | BU25: 0 | BV25: 0 | BW25: 0 | BX25: N/A | BY25: 0
A26: 24 | B26: BAC | C26: BofA Finance LLC | D26: Financials | E26: 2026 | F26: 3411738 | G26: N/A | H26: N/A | I26: 3108495 | J26: 261693 | K26: 37695 | L26: 113097 | M26: 30509 | N26: 12613 | O26: N/A | P26: 317816 | Q26: 303243 | R26: N/A | S26: 2314 | T26: N/A | U26: 12516 | V26: 73331 | W26: 3261519 | X26: N/A | Y26: N/A | Z26: 2965960 | AA26: 29254 | AB26: 101887 | AC26: 27132 | AD26: -8805 | AE26: N/A | AF26: 283279 | AG26: 295559 | AH26: 105856 | AI26: 3261299 | AJ26: 37695 | AK26: 29254 | AL26: 7186 | AM26: 2122 | AN26: N/A | AO26: N/A | AP26: N/A | AQ26: N/A | AR26: 69021 | AS26: 2200 | AT26: 45999 | AU26: N/A | AV26: 161560 | AW26: 177404 | AX26: 363815 | AY26: 314010 | AZ26: 202255 | BA26: N/A | BB26: 7212.5 | BC26: 7610.9 | BD26: N/A | BE26: 12168 | BF26: N/A | BG26: 2189 | BH26: -145157 | BI26: -90693 | BJ26: N/A | BK26: N/A | BL26: N/A | BM26: N/A | BN26: N/A | BO26: N/A | BP26: N/A | BQ26: N/A | BR26: N/A | BS26: N/A | BT26: N/A | BU26: N/A | BV26: N/A | BW26: 0 | BX26: 0 | BY26: 0
A27: 25 | B27: COR | C27: CENCORA, INC. | D27: Health Care | E27: 2026 | F27: 76590.1 | G27: 52239.1 | H27: 57820.5 | I27: 76590.1 | J27: 6534.2 | K27: 2628.6 | L27: 321332.8 | M27: 1554.2 | N27: 3875.1 | O27: 11478.5 | P27: 7660.8 | Q27: 1508 | R27: 6493.8 | S27: 1051.1 | T27: 25225.3 | U27: 2539.1 | V27: 125.3 | W27: 67101.7 | X27: 47717.8 | Y27: 54277.1 | Z27: 67101.7 | AA27: 2175.2 | AB27: 293958.6 | AC27: 1509.1 | AD27: 3484.7 | AE27: 9910 | AF27: 4388.1 | AG27: 645.9 | AH27: 293958.6 | AI27: 67101.7 | AJ27: 2258.3 | AK27: 2004 | AL27: 690.5 | AM27: 484.7 | AN27: 668 | AO27: 487.2 | AP27: 20492.5 | AQ27: 18998.8 | AR27: 13676.5 | AS27: 3774.2 | AT27: 117.8 | AU27: N/A | AV27: 4356.1 | AW27: 3132.6 | AX27: 7778.6 | AY27: 4964.4 | AZ27: 3422.4 | BA27: 3207.1 | BB27: 193.9 | BC27: 194.9 | BD27: 23871.8 | BE27: 2181.4 | BF27: 5661.1 | BG27: 1092 | BH27: -4977.3 | BI27: -618.1 | BJ27: 54719.8 | BK27: 50942.2 | BL27: N/A | BM27: N/A | BN27: N/A | BO27: 309854.3 | BP27: 284048.6 | BQ27: 0 | BR27: 0 | BS27: 0 | BT27: 0 | BU27: 0 | BV27: 0 | BW27: 0 | BX27: 0 | BY27: 0
A28: 26 | B28: NKE | C28: NIKE, Inc. | D28: Consumer Discretionary | E28: 2026 | F28: 36579 | G28: 23362 | H28: 10566 | I28: 36579 | J28: -727 | K28: 3885 | L28: 46309 | M28: 3219 | N28: 3698 | O28: 19790 | P28: 7961 | Q28: 13213 | R28: 16088 | S28: 775 | T28: 4717 | U28: 4828 | V28: N/A | W28: 38110 | X28: 25382 | Y28: 10593 | Z28: 38110 | AA28: 6700 | AB28: 51362 | AC28: 5700 | AD28: 7429 | AE28: 22887 | AF28: 8903 | AG28: 14430 | AH28: 51362 | AI28: 38110 | AJ28: 3885 | AK28: 6700 | AL28: 666 | AM28: 1000 | AN28: 430 | AO28: 812 | AP28: 2715 | AQ28: 2041 | AR28: 240 | AS28: 99 | AT28: 5 | AU28: N/A | AV28: 7464 | AW28: 9860 | AX28: 7966 | AY28: 8909 | AZ28: 502 | BA28: 3268 | BB28: N/A | BC28: N/A | BD28: 4427 | BE28: 5000 | BF28: 16576 | BG28: 796 | BH28: -275 | BI28: 894 | BJ28: 3479 | BK28: 2851 | BL28: N/A | BM28: N/A | BN28: 669 | BO28: 26519 | BP28: 28475 | BQ28: 0 | BR28: 0 | BS28: 0 | BT28: 0 | BU28: 0 | BV28: 0 | BW28: 0 | BX28: 0 | BY28: 0
A29: 27 | B29: ELS | C29: EQUITY LIFESTYLE PROPERTIES, INC. | D29: Real Estate | E29: 2026 | F29: 5745.4 | G29: N/A | H29: N/A | I29: 3930.6 | J29: N/A | K29: 391.3 | L29: 1531.4 | M29: 402.1 | N29: 571.1 | O29: 82.4 | P29: 3345.9 | Q29: 1756.3 | R29: 37.5 | S29: 131.5 | T29: 1.2 | U29: 372.8 | V29: 131 | W29: 5645.7 | X29: N/A | Y29: N/A | Z29: 3821.9 | AA29: 380.7 | AB29: 1526.2 | AC29: 384.8 | AD29: 596.7 | AE29: 84.8 | AF29: 3204.7 | AG29: 1740.7 | AH29: 1526.2 | AI29: 5645.7 | AJ29: N/A | AK29: N/A | AL29: -3.3 | AM29: -0.4 | AN29: 237.1 | AO29: 241.3 | AP29: 1.6 | AQ29: N/A | AR29: 17.6 | AS29: 38 | AT29: N/A | AU29: N/A | AV29: 37.1 | AW29: 70.5 | AX29: 3345.9 | AY29: 3204.7 | AZ29: 3308.7 | BA29: 334.1 | BB29: 193.8 | BC29: 191.1 | BD29: 1.2 | BE29: 249.3 | BF29: 38.5 | BG29: 122.7 | BH29: -277.1 | BI29: -217.8 | BJ29: N/A | BK29: N/A | BL29: 85.6 | BM29: 81.5 | BN29: N/A | BO29: N/A | BP29: N/A | BQ29: 0 | BR29: 0 | BS29: 0 | BT29: N/A | BU29: N/A | BV29: N/A | BW29: 0 | BX29: 0 | BY29: N/A
A30: 28 | B30: IVZ | C30: Invesco Ltd. | D30: Financials | E30: 2026 | F30: 27094 | G30: 3907.6 | H30: 2713 | I30: 14089.1 | J30: 5886.8 | K30: -695.7 | L30: 5314.1 | M30: 538 | N30: 1525.3 | O30: -1758.7 | P30: 1825.1 | Q30: 12231 | R30: 576.5 | S30: 155.9 | T30: 449.4 | U30: 378.9 | V30: 70.5 | W30: 27008.9 | X30: 3834.1 | Y30: 2974.4 | Z30: 11340.1 | AA30: 832.1 | AB30: 5160.3 | AC30: -333.7 | AD30: 1190 | AE30: -74.6 | AF30: 890.6 | AG30: 14559.9 | AH30: 5160.3 | AI30: 27008.9 | AJ30: -379.4 | AK30: 1005.3 | AL30: -204.6 | AM30: 252.9 | AN30: 84.3 | AO30: 69.1 | AP30: N/A | AQ30: N/A | AR30: 8477.1 | AS30: 5848.1 | AT30: N/A | AU30: N/A | AV30: 1037.5 | AW30: 986.5 | AX30: 1825.1 | AY30: 890.6 | AZ30: 787.6 | BA30: 1441 | BB30: 444 | BC30: 448 | BD30: 424.4 | BE30: 479 | BF30: 594.7 | BG30: 179.6 | BH30: -974.4 | BI30: 68.4 | BJ30: 287.9 | BK30: 272.6 | BL30: 60.4 | BM30: 87.7 | BN30: 77.9 | BO30: 7072.8 | BP30: 5234.9 | BQ30: 0 | BR30: 0 | BS30: N/A | BT30: N/A | BU30: 0 | BV30: 0 | BW30: 0 | BX30: 0 | BY30: 0
A31: 29 | B31: AMP | C31: AMERIPRISE FINANCIAL INC | D31: Financials | E31: 2026 | F31: 190904 | G31: N/A | H31: N/A | I31: 184355 | J31: 27662 | K31: 4504 | L31: 18911 | M31: 3563 | N31: 8323 | O31: N/A | P31: 2249 | Q31: 6549 | R31: 3875 | S31: 151 | T31: 403 | U31: 744 | V31: 170 | W31: 190904 | X31: N/A | Y31: N/A | Z31: 184355 | AA31: 4504 | AB31: 18911 | AC31: 3563 | AD31: 8323 | AE31: N/A | AF31: 2027 | AG31: 6549 | AH31: 17926 | AI31: 181403 | AJ31: 4504 | AK31: 4504 | AL31: 941 | AM31: 941 | AN31: 162 | AO31: 162 | AP31: N/A | AQ31: N/A | AR31: 1440 | AS31: 356 | AT31: N/A | AU31: N/A | AV31: 2318 | AW31: 2357 | AX31: 2249 | AY31: 2027 | AZ31: -69 | BA31: 8161 | BB31: 338.1 | BC31: 338.1 | BD31: 400 | BE31: 744 | BF31: 3875 | BG31: 151 | BH31: -1528 | BI31: -1528 | BJ31: N/A | BK31: N/A | BL31: N/A | BM31: N/A | BN31: N/A | BO31: N/A | BP31: N/A | BQ31: 0 | BR31: 0 | BS31: N/A | BT31: N/A | BU31: N/A | BV31: N/A | BW31: 0 | BX31: 0 | BY31: 0
A32: 30 | B32: ZBH | C32: ZIMMER BIOMET HOLDINGS, INC. | D32: Health Care | E32: 2026 | F32: 23091.7 | G32: 5119.9 | H32: 2583.7 | I32: 10386 | J32: 11611 | K32: 1098.1 | L32: 8231.5 | M32: 705.1 | N32: 1697.1 | O32: 1285.4 | P32: 1000 | Q32: 12697.7 | R32: 3257.2 | S32: 1093.8 | T32: 1704.4 | U32: 2207.1 | V32: 327.5 | W32: 21365.3 | X32: 4671.5 | Y32: 2450.9 | Z32: 8889.1 | AA32: 1285.7 | AB32: 7678.6 | AC32: 903.8 | AD32: 1499.4 | AE32: 1210.2 | AF32: 1000 | AG32: 12468.1 | AH32: 7678.6 | AI32: 21365.3 | AJ32: 830.8 | AK32: 1036.6 | AL32: 125.7 | AM32: 131.4 | AN32: 224.5 | AO32: 203.8 | AP32: 2286.4 | AQ32: 2235.3 | AR32: 9947.1 | AS32: 4717.3 | AT32: 0.5 | AU32: 225.6 | AV32: 591.9 | AW32: 525.5 | AX32: 1000.5 | AY32: 1100.1 | AZ32: 408.6 | BA32: 1472.6 | BB32: 318.7 | BC32: 317.5 | BD32: 1480.7 | BE32: 2048.8 | BF32: 2929.8 | BG32: 996.3 | BH32: -1975.7 | BI32: -888.1 | BJ32: 303 | BK32: 194.6 | BL32: N/A | BM32: N/A | BN32: 61.2 | BO32: 2493.7 | BP32: 2191.2 | BQ32: 0 | BR32: 0 | BS32: 0 | BT32: 0 | BU32: 0 | BV32: 0 | BW32: 0 | BX32: 0 | BY32: 0
A33: 31 | B33: CEVA | C33: Ceva, Inc. | D33: Information Technology | E33: 2026 | F33: 388.3 | G33: 284.8 | H33: 28.7 | I33: 388.3 | J33: 0 | K33: -11.3 | L33: 87.5 | M33: -10.6 | N33: -3.4 | O33: 95.4 | P33: N/A | Q33: 336.5 | R33: 18.1 | S33: 3.4 | T33: 49.4 | U33: 7.1 | V33: N/A | W33: 308.9 | X33: 216.3 | Y33: 30.5 | Z33: 308.9 | AA33: -7.5 | AB33: 72.7 | AC33: -8.8 | AD33: 3.5 | AE33: 94.2 | AF33: N/A | AG33: 266.6 | AH33: 72.7 | AI33: 308.9 | AJ33: -4.7 | AK33: -2.8 | AL33: 5.9 | AM33: 6 | AN33: 2.9 | AO33: 3 | AP33: 0.3 | AQ33: 0.3 | AR33: 58.3 | AS33: 1 | AT33: N/A | AU33: 74.8 | AV33: 40.6 | AW33: 18.5 | AX33: N/A | AY33: N/A | AZ33: N/A | BA33: -6.3 | BB33: 27.5 | BC33: 23.6 | BD33: 37.2 | BE33: 6.9 | BF33: 16.9 | BG33: 3 | BH33: -34 | BI33: -2.4 | BJ33: 3 | BK33: 3.5 | BL33: 4.4 | BM33: 6.3 | BN33: 1.5 | BO33: 14.2 | BP33: 12.8 | BQ33: 0 | BR33: 0 | BS33: 0 | BT33: 0 | BU33: 0 | BV33: 0 | BW33: 0 | BX33: 0 | BY33: 0
A34: 32 | B34: EHC | C34: Encompass Health Corporation | D34: Health Care | E34: 2026 | F34: 7089.7 | G34: 905.9 | H34: 836.4 | I34: 3813.9 | J34: 1289.4 | K34: 539.5 | L34: 5935.2 | M34: 566.2 | N34: 705.8 | O34: N/A | P34: 1254.7 | Q34: 2438.2 | R34: 236.2 | S34: 327.9 | T34: 613.4 | U34: 1959.3 | V34: 143.5 | W34: 6534.7 | X34: 886.9 | Y34: 841 | Z34: 3685.5 | AA34: 151.9 | AB34: 5373.2 | AC34: 455.7 | AD34: 715.8 | AE34: N/A | AF34: 1511.3 | AG34: 2067 | AH34: 5373.2 | AI34: 6534.7 | AJ34: 953 | AK34: 749.6 | AL34: 192.9 | AM34: 150.2 | AN34: 564.8 | AO34: 528.9 | AP34: N/A | AQ34: N/A | AR34: 1317.6 | AS34: 308.3 | AT34: -18.9 | AU34: N/A | AV34: 72.2 | AW34: 85.4 | AX34: 1235.8 | AY34: 1511.3 | AZ34: 1163.6 | BA34: 141 | BB34: 116 | BC34: 116 | BD34: 593 | BE34: 1634.8 | BF34: 209.2 | BG34: 299.6 | BH34: -764.6 | BI34: -653.3 | BJ34: 178.2 | BK34: 171 | BL34: N/A | BM34: N/A | BN34: N/A | BO34: N/A | BP34: N/A | BQ34: 0 | BR34: 0 | BS34: N/A | BT34: N/A | BU34: N/A | BV34: N/A | BW34: 0 | BX34: 0 | BY34: 0
A35: 33 | B35: TOL | C35: Toll Brothers, Inc. | D35: Consumer Discretionary | E35: 2026 | F35: 14519.9 | G35: N/A | H35: N/A | I35: 6233.8 | J35: 8574.8 | K35: 1720.6 | L35: 7143.3 | M35: 1346.5 | N35: 1112.4 | O35: 524.5 | P35: N/A | Q35: 8270.7 | R35: 1033.6 | S35: 82.1 | T35: N/A | U35: 273.4 | V35: N/A | W35: 13367.9 | X35: N/A | Y35: N/A | Z35: 5681.2 | AA35: 2040.2 | AB35: 10846.7 | AC35: 446.7 | AD35: 1010.2 | AE35: 524.5 | AF35: N/A | AG35: 7670.9 | AH35: N/A | AI35: 13367.9 | AJ35: 1791.4 | AK35: N/A | AL35: 444.9 | AM35: 514.4 | AN35: 86.2 | AO35: 73.6 | AP35: N/A | AQ35: N/A | AR35: N/A | AS35: N/A | AT35: N/A | AU35: N/A | AV35: 1259 | AW35: 1303 | AX35: N/A | AY35: N/A | AZ35: N/A | BA35: 1026.2 | BB35: 94.8 | BC35: 99.8 | BD35: N/A | BE35: 453 | BF35: 982.3 | BG35: 81.2 | BH35: -310 | BI35: -167.6 | BJ35: N/A | BK35: N/A | BL35: 51.1 | BM35: 52.9 | BN35: 16.8 | BO35: 8212.5 | BP35: 7824.3 | BQ35: N/A | BR35: N/A | BS35: N/A | BT35: N/A | BU35: N/A | BV35: N/A | BW35: 0 | BX35: 0 | BY35: 0
A36: 34 | B36: CLX | C36: CLOROX CO /DE/ | D36: Consumer Staples | E36: 2026 | F36: 5561 | G36: 1608 | H36: 1919 | I36: 5079 | J36: 432 | K36: 1078 | L36: 6124 | M36: 810 | N36: 981 | O36: 3213 | P36: 2484 | Q36: 321 | R36: 1124 | S36: 165 | T36: 821 | U36: 1267 | V36: 88 | W36: 5751 | X36: 1622 | Y36: 1574 | Z36: 5259 | AA36: 398 | AB36: 6124 | AC36: 280 | AD36: 695 | AE36: 3048 | AF36: 2481 | AG36: 328 | AH36: 6124 | AI36: 5751 | AJ36: 1078 | AK36: 398 | AL36: 254 | AM36: 106 | AN36: 220 | AO36: 212 | AP36: 523 | AQ36: 637 | AR36: 1229 | AS36: 929 | AT36: 202 | AU36: 121 | AV36: 167 | AW36: 202 | AX36: 2686 | AY36: 2781 | AZ36: 2519 | BA36: 761 | BB36: 122.7 | BC36: 124.2 | BD36: 695 | BE36: 1315 | BF36: 1167 | BG36: 169 | BH36: -94 | BI36: -175 | BJ36: 838 | BK36: 950 | BL36: N/A | BM36: N/A | BN36: N/A | BO36: 3891 | BP36: 4045 | BQ36: 0 | BR36: 0 | BS36: 0 | BT36: 0 | BU36: 0 | BV36: 0 | BW36: 0 | BX36: 0 | BY36: 0
A37: 35 | B37: GRBK | C37: Green Brick Partners, Inc. | D37: Consumer Discretionary | E37: 2026 | F37: 2534.8 | G37: 15.1 | H37: 4.3 | I37: 601.8 | J37: 1567.1 | K37: 71.8 | L37: 2098.5 | M37: 313.2 | N37: 213.2 | O37: 640.8 | P37: 323.3 | Q37: 1859 | R37: 231.4 | S37: 5.1 | T37: 9.3 | U37: 6.3 | V37: N/A | W37: 2534.8 | X37: 36.1 | Y37: 185.2 | Z37: 601.8 | AA37: 59.4 | AB37: 2040 | AC37: 313.2 | AD37: 213.2 | AE37: 640.8 | AF37: 323.3 | AG37: 1859 | AH37: 1503.2 | AI37: 2250 | AJ37: 438.2 | AK37: 438.2 | AL37: 94.7 | AM37: 94.7 | AN37: 4.8 | AO37: 4.8 | AP37: 13.4 | AQ37: 13.4 | AR37: 0.7 | AS37: 0.2 | AT37: 0.5 | AU37: N/A | AV37: 35.2 | AW37: 19.9 | AX37: 323.7 | AY37: 323.7 | AZ37: 288.6 | BA37: 208.4 | BB37: 43.2 | BC37: 43.2 | BD37: 13.6 | BE37: 6.3 | BF37: 231.4 | BG37: 5.1 | BH37: -43.6 | BI37: -43.6 | BJ37: 0.1 | BK37: 11.6 | BL37: 25.7 | BM37: 25.7 | BN37: N/A | BO37: 1457.7 | BP37: 1399.2 | BQ37: 0 | BR37: 0 | BS37: 0 | BT37: 0 | BU37: 0 | BV37: 0 | BW37: 0 | BX37: 0 | BY37: 0
A38: 36 | B38: ED | C38: CONSOLIDATED EDISON INC | D38: Utilities | E38: 2026 | F38: 74603 | G38: 6750 | H38: 6614 | I38: 74603 | J38: 14857 | K38: 2935 | L38: 16918 | M38: 2023 | N38: 4800 | O38: 2931 | P38: 25801 | Q38: 24190 | R38: N/A | S38: 2321 | T38: 2583 | U38: 55403 | V38: 1233 | W38: 70562 | X38: 6664 | Y38: 6433 | Z38: 70562 | AA38: 2670 | AB38: 15256 | AC38: 1820 | AD38: 3614 | AE38: 2732 | AF38: 24710 | AG38: 21962 | AH38: 15256 | AI38: 70562 | AJ38: 2597 | AK38: 2138 | AL38: 574 | AM38: 318 | AN38: 4465 | AO38: 3964 | AP38: N/A | AQ38: N/A | AR38: 406 | AS38: 1219 | AT38: 400 | AU38: 27 | AV38: 1629 | AW38: 1324 | AX38: 26201 | AY38: 24710 | AZ38: 24572 | BA38: 335 | BB38: 361.1 | BC38: 346.6 | BD38: 2440 | BE38: 52165 | BF38: N/A | BG38: 2155 | BH38: -5249 | BI38: -5273 | BJ38: 1947 | BK38: 1676 | BL38: 474 | BM38: 633 | BN38: 104 | BO38: 13987 | BP38: 12524 | BQ38: 0 | BR38: 0 | BS38: N/A | BT38: N/A | BU38: 0 | BV38: 0 | BW38: 0 | BX38: 0 | BY38: 0
A39: 37 | B39: GS | C39: The Goldman Sachs Group, Inc. | D39: Financials | E39: 2026 | F39: 1809320 | G39: N/A | H39: N/A | I39: 1684348 | J39: 165288 | K39: 21852 | L39: N/A | M39: 17176 | N39: -45154 | O39: N/A | P39: 236027 | Q39: 124972 | R39: N/A | S39: 2182 | T39: N/A | U39: 7474 | V39: 66814 | W39: 1675972 | X39: N/A | Y39: N/A | Z39: 1553976 | AA39: 18397 | AB39: N/A | AC39: 14276 | AD39: -13212 | AE39: N/A | AF39: 227579 | AG39: 121996 | AH39: N/A | AI39: 1675972 | AJ39: 21852 | AK39: 18397 | AL39: 4676 | AM39: 4121 | AN39: 2064 | AO39: 2091 | AP39: N/A | AQ39: N/A | AR39: 5949 | AS39: 429 | AT39: 69709 | AU39: N/A | AV39: 164259 | AW39: 182092 | AX39: 305736 | AY39: 303524 | AZ39: 141477 | BA39: -47218 | BB39: 296.5 | BC39: 310.7 | BD39: N/A | BE39: 8024 | BF39: N/A | BG39: 2392 | BH39: -44227 | BI39: -49624 | BJ39: N/A | BK39: N/A | BL39: 132 | BM39: N/A | BN39: N/A | BO39: N/A | BP39: N/A | BQ39: N/A | BR39: N/A | BS39: N/A | BT39: N/A | BU39: N/A | BV39: N/A | BW39: 0 | BX39: N/A | BY39: 0
A40: 38 | B40: INGR | C40: INGREDION INCORPORATED | D40: Consumer Staples | E40: 2026 | F40: 7897 | G40: 3505 | H40: 1316 | I40: 3531 | J40: 5610 | K40: 1016 | L40: 7219 | M40: 729 | N40: 944 | O40: 1828 | P40: 1766 | Q40: 4274 | R40: 579 | S40: 222 | T40: 1185 | U40: 2526 | V40: 59 | W40: 7444 | X40: 3355 | Y40: 1281 | Z40: 3554 | AA40: 883 | AB40: 1757 | AC40: 165 | AD40: 1436 | AE40: 430 | AF40: 1931 | AG40: 3804 | AH40: 1816 | AI40: 7444 | AJ40: 974 | AK40: 931 | AL40: 238 | AM40: 277 | AN40: 433 | AO40: 301 | AP40: 1227 | AQ40: 1187 | AR40: 922 | AS40: 347 | AT40: 58 | AU40: 71 | AV40: 1030 | AW40: 997 | AX40: 1824 | AY40: 2013 | AZ40: 794 | BA40: 511 | BB40: 64.5 | BC40: 65.2 | BD40: 1093 | BE40: 2264 | BF40: 555 | BG40: 214 | BH40: -444 | BI40: -47 | BJ40: 693 | BK40: 604 | BL40: N/A | BM40: N/A | BN40: 26 | BO40: 5391 | BP40: 5639 | BQ40: 0 | BR40: 0 | BS40: 0 | BT40: 0 | BU40: 0 | BV40: 0 | BW40: 0 | BX40: 0 | BY40: 0
...

Sheet Ratios_Scores
A1: RATIOS & SCORES — 5 Bankruptcy Models + Extended Analytics
A2: Ticker | B2: Company Name | C2: Working Capital ($M) | D2: EBIT Margin | E2: EBT Margin | F2: Net Margin | G2: ROA Y0 | H2: ROA Y1 | I2: ROE | J2: ROCE | K2: Gross Margin Y0 | L2: Gross Margin Y1 | M2: Asset Turnover Y0 | N2: Asset Turnover Y1 | O2: Current Ratio Y0 | P2: Current Ratio Y1 | Q2: Quick Ratio Y0 | R2: Cash Ratio Y0 | S2: Leverage Y0 | T2: Leverage Y1 | U2: Debt/Equity Y0 | V2: Net Debt/Equity | W2: CFO / Net Income | X2: FCF Margin | Y2: R&D % Revenue | Z2: Interest Coverage | AA2: Revenue Growth | AB2: NI Growth | AC2: Accruals Ratio | AD2: Sloan Accrual | AE2: Z68: X1 | AF2: Z68: X2 | AG2: Z68: X3 | AH2: Z68: X4 | AI2: Z68: X5 | AJ2: Z-Score (1968) | AK2: Z-Band (1968) | AL2: Z': X1 | AM2: Z': X2 | AN2: Z': X3 | AO2: Z': X4 | AP2: Z': X5 | AQ2: Z'-Score (1983) | AR2: Z'-Band (1983) | AS2: Z'': X1 | AT2: Z'': X2 | AU2: Z'': X3 | AV2: Z'': X4 | AW2: Z''-Score (1995) | AX2: Z''-Band (1995) | AY2: SS: A | AZ2: SS: B | BA2: SS: C | BB2: SS: D | BC2: S-Score (Springate) | BD2: S-Band (Springate) | BE2: ZM: ROA | BF2: ZM: Leverage | BG2: ZM: Liquidity | BH2: X-Score (Zmijewski) | BI2: X-Prob (%) | BJ2: X-Band (Zmijewski) | BK2: F1 ROA>0 | BL2: F2 CFO>0 | BM2: F3 ROA Impr | BN2: F4 CFO>ROA | BO2: F5 Lev Down | BP2: F6 Liq Up | BQ2: F7 No Dilution | BR2: F8 GM Up | BS2: F9 AT Up | BT2: F-Score | BU2: F-Interpretation | BV2: DSRI | BW2: GMI | BX2: AQI | BY2: SGI | BZ2: DEPI | CA2: SGAI | CB2: LVGI | CC2: TATA | CD2: M-Score (Beneish) | CE2: M-Flag | CF2: Net Debt/EBITDA | CG2: Health Score (0-100) | CH2: TGTBT Score | CI2: TGTBT Flag
A3: AVY | B3: AVERY DENNISON CORPORATION | C3: 336700000 | D3: 0.1 | E3: 0.1 | F3: 0.08 | G3: 0.08 | H3: 0.08 | I3: 0.31 | J3: 0.15 | K3: 0.29 | L3: 0.29 | M3: 1.01 | N3: 1.04 | O3: 1.13 | P3: 1.08 | Q3: 0.76 | R3: 0.08 | S3: 1 | T3: 1 | U3: 1.66 | V3: 1.57 | W3: 1.28 | X3: 0.08 | Y3: 0.02 | Z3: 7.77 | AA3: 0.01 | AB3: -0.02 | AC3: -0.02 | AD3: -0.02 | AE3: 0.04 | AF3: 0.64 | AG3: 0.11 | AH3: 0.25 | AI3: 1.01 | AJ3: 2.44 | AK3: Grey | AL3: 0.04 | AM3: 0.64 | AN3: 0.11 | AO3: 0.25 | AP3: 1.01 | AQ3: 2 | AR3: Grey | AS3: 0.04 | AT3: 0.64 | AU3: 0.11 | AV3: 0.25 | AW3: 3.3 | AX3: Safe | AY3: 0.04 | AZ3: 0.11 | BA3: 0.35 | BB3: 1.01 | BC3: 0.99 | BD3: Healthy | BE3: 0.08 | BF3: 1 | BG3: 1.13 | BH3: 0.99 | BI3: 0.73 | BJ3: Distress | BK3: 1 | BL3: 1 | BM3: 0 | BN3: 1 | BO3: 0 | BP3: 1 | BQ3: 1 | BR3: 0 | BS3: 0 | BT3: 5 | BU3: Mixed | BV3: 1.01 | BW3: 1.01 | BX3: 1.06 | BY3: 1.01 | BZ3: 0.99 | CA3: 0.99 | CB3: 1 | CC3: -0.02 | CD3: -2.53 | CE3: Lower Risk | CF3: 2.81 | CG3: 49.96 | CH3: 0 | CI3: CLEAR
A4: CHD | B4: CHURCH & DWIGHT CO., INC. | C4: 99300000 | D4: 0.17 | E4: 0.15 | F4: 0.12 | G4: 0.08 | H4: 0.07 | I4: 0.18 | J4: 0.15 | K4: 0.45 | L4: 0.46 | M4: 0.7 | N4: 0.69 | O4: 1.07 | P4: 1.7 | Q4: 0.71 | R4: 0.27 | S4: 0.55 | T4: 0.51 | U4: 0.55 | V4: 0.45 | W4: 1.65 | X4: 0.18 | Y4: 0.02 | Z4: 11.32 | AA4: 0.02 | AB4: 0.26 | AC4: -0.05 | AD4: -0.05 | AE4: 0.01 | AF4: 0.76 | AG4: 0.12 | AH4: 0.82 | AI4: 0.7 | AJ4: 2.66 | AK4: Grey | AL4: 0.01 | AM4: 0.76 | AN4: 0.12 | AO4: 0.82 | AP4: 0.7 | AQ4: 2.06 | AR4: Grey | AS4: 0.01 | AT4: 0.76 | AU4: 0.12 | AV4: 0.82 | AW4: 4.22 | AX4: Safe | AY4: 0.01 | AZ4: 0.12 | BA4: 0.64 | BB4: 0.7 | BC4: 1.08 | BD4: Healthy | BE4: 0.08 | BF4: 0.55 | BG4: 1.07 | BH4: -1.58 | BI4: 0.17 | BJ4: Healthy | BK4: 1 | BL4: 1 | BM4: 1 | BN4: 1 | BO4: 1 | BP4: 0 | BQ4: 1 | BR4: 0 | BS4: 1 | BT4: 7 | BU4: Strong | BV4: 0.97 | BW4: 1.02 | BX4: 1.13 | BY4: 1.02 | BZ4: 0.88 | CA4: 1.05 | CB4: 1.08 | CC4: -0.05 | CD4: -2.73 | CE4: Lower Risk | CF4: 1.36 | CG4: 58.64 | CH4: 0 | CI4: CLEAR
A5: GWW | B5: W.W. GRAINGER, INC. | C5: 3544000000 | D5: 0.14 | E5: 0.14 | F5: 0.1 | G5: 0.19 | H5: 0.22 | I5: 0.46 | J5: 0.36 | K5: 0.39 | L5: 0.39 | M5: 2 | N5: 1.94 | O5: 2.83 | P5: 2.49 | Q5: 1.59 | R5: 0.3 | S5: 1 | T5: 1 | U5: 0.67 | V5: 0.51 | W5: 1.18 | X5: 0.07 | Y5: 0 | Z5: 28.35 | AA5: 0.05 | AB5: -0.11 | AC5: -0.03 | AD5: -0.03 | AE5: 0.4 | AF5: 1.67 | AG5: 0.28 | AH5: 0.42 | AI5: 2 | AJ5: 5.98 | AK5: Safe | AL5: 0.4 | AM5: 1.67 | AN5: 0.28 | AO5: 0.42 | AP5: 2 | AQ5: 4.74 | AR5: Safe | AS5: 0.4 | AT5: 1.67 | AU5: 0.28 | AV5: 0.42 | AW5: 10.34 | AX5: Safe | AY5: 0.4 | AZ5: 0.28 | BA5: 1.25 | BB5: 2 | BC5: 2.89 | BD5: Healthy | BE5: 0.19 | BF5: 1 | BG5: 2.83 | BH5: 0.5 | BI5: 0.62 | BJ5: Distress | BK5: 1 | BL5: 1 | BM5: 0 | BN5: 1 | BO5: 1 | BP5: 1 | BQ5: 1 | BR5: 0 | BS5: 1 | BT5: 7 | BU5: Strong | BV5: 1 | BW5: 1.01 | BX5: 1.02 | BY5: 1.05 | BZ5: 1.09 | CA5: 1.05 | CB5: 1 | CC5: -0.03 | CD5: -2.59 | CE5: Lower Risk | CF5: 0.69 | CG5: 67.3 | CH5: 0 | CI5: CLEAR
A6: SO | B6: SOUTHERN CO | C6: -5971000000 | D6: 0.25 | E6: 0.17 | F6: 0.15 | G6: 0.03 | H6: 0.03 | I6: 0.12 | J6: 0.05 | K6: N/A | L6: N/A | M6: 0.19 | N6: 0.18 | O6: 0.65 | P6: 0.67 | Q6: 0.65 | R6: 0.1 | S6: 0.75 | T6: 0.75 | U6: 0.02 | V6: -0.03 | W6: 2.26 | X6: -0.1 | Y6: 0 | Z6: N/A | AA6: 0.11 | AB6: -0.01 | AC6: -0.04 | AD6: -0.04 | AE6: -0.04 | AF6: 0.1 | AG6: 0.05 | AH6: 0.31 | AI6: 0.19 | AJ6: 0.62 | AK6: Distress | AL6: -0.04 | AM6: 0.1 | AN6: 0.05 | AO6: 0.31 | AP6: 0.19 | AQ6: 0.52 | AR6: Distress | AS6: -0.04 | AT6: 0.1 | AU6: 0.05 | AV6: 0.31 | AW6: 0.7 | AX6: Distress | AY6: -0.04 | AZ6: 0.05 | BA6: 0.3 | BB6: 0.19 | BC6: 0.38 | BD6: Distress | BE6: 0.03 | BF6: 0.75 | BG6: 0.65 | BH6: -0.2 | BI6: 0.45 | BJ6: Healthy | BK6: 1 | BL6: 1 | BM6: 0 | BN6: 1 | BO6: 0 | BP6: 0 | BQ6: 1 | BR6: 0 | BS6: 1 | BT6: 5 | BU6: Mixed | BV6: 0.93 | BW6: N/A | BX6: 1.05 | BY6: 1.11 | BZ6: 1.15 | CA6: N/A | CB6: 1 | CC6: -0.04 | CD6: N/A | CE6: N/A | CF6: -0.13 | CG6: 44.76 | CH6: 0 | CI6: CLEAR
A7: VICI | B7: VICI Properties Inc. | C7: N/A | D7: 0.08 | E7: 0.7 | F7: 0.69 | G7: 0.06 | H7: 0.06 | I7: 0.1 | J7: N/A | K7: 0.99 | L7: 0.99 | M7: 0.09 | N7: 0.08 | O7: N/A | P7: N/A | Q7: N/A | R7: N/A | S7: 0.4 | T7: 0.41 | U7: 0.6 | V7: 0.58 | W7: 0.9 | X7: 0.63 | Y7: 0 | Z7: 0.39 | AA7: 0.04 | AB7: 0.04 | AC7: 0.01 | AD7: 0.01 | AE7: N/A | AF7: 0.06 | AG7: 0.01 | AH7: 1.5 | AI7: 0.09 | AJ7: N/A | AK7: N/A | AL7: N/A | AM7: 0.06 | AN7: 0.01 | AO7: 1.5 | AP7: 0.09 | AQ7: N/A | AR7: N/A | AS7: N/A | AT7: 0.06 | AU7: 0.01 | AV7: 1.5 | AW7: N/A | AX7: N/A | AY7: N/A | AZ7: 0.01 | BA7: N/A | BB7: 0.09 | BC7: N/A | BD7: N/A | BE7: 0.06 | BF7: 0.4 | BG7: N/A | BH7: N/A | BI7: N/A | BJ7: N/A | BK7: 1 | BL7: 1 | BM7: 1 | BN7: 0 | BO7: 1 | BP7: 0 | BQ7: 0 | BR7: 1 | BS7: 1 | BT7: 6 | BU7: Mixed | BV7: N/A | BW7: 1 | BX7: 1 | BY7: 1.04 | BZ7: 1.09 | CA7: 0.9 | CB7: 0.98 | CC7: 0.01 | CD7: N/A | CE7: N/A | CF7: 49.93 | CG7: 48.46 | CH7: 0 | CI7: CLEAR
A8: MPWR | B8: MONOLITHIC POWER SYSTEMS INC | C8: 1814437000 | D8: 2.19 | E8: 2.3 | F8: 1.87 | G8: 0.15 | H8: 0.11 | I8: 0.18 | J8: 0.19 | K8: 4.62 | L8: 3.98 | M8: 0.08 | N8: 0.07 | O8: 5.91 | P8: 4.77 | Q8: 4.38 | R8: 2.98 | S8: 0.16 | T8: 0.18 | U8: N/A | V8: N/A | W8: 1.35 | X8: 2 | Y8: 0.13 | Z8: N/A | AA8: 0.18 | AB8: 0.38 | AC8: -0.05 | AD8: -0.05 | AE8: 0.43 | AF8: 0.62 | AG8: 0.17 | AH8: 5.33 | AI8: 0.08 | AJ8: 5.24 | AK8: Safe | AL8: 0.43 | AM8: 0.62 | AN8: 0.17 | AO8: 5.33 | AP8: 0.08 | AQ8: 3.69 | AR8: Safe | AS8: 0.43 | AT8: 0.62 | AU8: 0.17 | AV8: 5.33 | AW8: 11.63 | AX8: Safe | AY8: 0.43 | AZ8: 0.17 | BA8: 2.07 | BB8: 0.08 | BC8: 2.38 | BD8: Healthy | BE8: 0.15 | BF8: 0.16 | BG8: 5.91 | BH8: -4.08 | BI8: 0.02 | BJ8: Healthy | BK8: 1 | BL8: 1 | BM8: 1 | BN8: 1 | BO8: 0 | BP8: 1 | BQ8: 0 | BR8: 1 | BS8: 1 | BT8: 7 | BU8: Strong | BV8: 0.9 | BW8: 0.86 | BX8: 0.97 | BY8: 1.18 | BZ8: 0.74 | CA8: 1.17 | CB8: 0.89 | CC8: -0.05 | CD8: -2.76 | CE8: Lower Risk | CF8: N/A | CG8: 66.7 | CH8: 0 | CI8: CLEAR
A9: EWBC | B9: EAST WEST BANCORP INC | C9: N/A | D9: 31.19 | E9: 31.19 | F9: 23.96 | G9: 0.02 | H9: 0.02 | I9: 0.15 | J9: N/A | K9: -0.02 | L9: -0.02 | M9: 0 | N9: 0 | O9: N/A | P9: N/A | Q9: N/A | R9: N/A | S9: 0.89 | T9: 0.9 | U9: 0.02 | V9: -0.45 | W9: 1.13 | X9: 27.04 | Y9: 0 | Z9: 1.25 | AA9: 0.03 | AB9: 0.14 | AC9: 0 | AD9: 0 | AE9: N/A | AF9: 0.1 | AG9: 0.02 | AH9: 0.12 | AI9: 0 | AJ9: N/A | AK9: N/A | AL9: N/A | AM9: 0.1 | AN9: 0.02 | AO9: 0.12 | AP9: 0 | AQ9: N/A | AR9: N/A | AS9: N/A | AT9: 0.1 | AU9: 0.02 | AV9: 0.12 | AW9: N/A | AX9: N/A | AY9: N/A | AZ9: 0.02 | BA9: N/A | BB9: 0 | BC9: N/A | BD9: N/A | BE9: 0.02 | BF9: 0.89 | BG9: N/A | BH9: N/A | BI9: N/A | BJ9: N/A | BK9: 1 | BL9: 1 | BM9: 1 | BN9: 1 | BO9: 1 | BP9: 0 | BQ9: 0 | BR9: 1 | BS9: 0 | BT9: 6 | BU9: Mixed | BV9: N/A | BW9: N/A | BX9: 1 | BY9: 1.03 | BZ9: 0.98 | CA9: N/A | CB9: 0.99 | CC9: 0 | CD9: N/A | CE9: N/A | CF9: -2.07 | CG9: 46.83 | CH9: 0 | CI9: CLEAR
A10: BEN | B10: FRANKLIN RESOURCES, INC. | C10: 6304704000 | D10: 0.1 | E10: 0.14 | F10: 0.09 | G10: 0.02 | H10: 0.01 | I10: 0.04 | J10: 0.02 | K10: -0.41 | L10: -0.28 | M10: 0.18 | N10: 0.19 | O10: 5.81 | P10: 6.32 | Q10: 5.81 | R10: 3.54 | S10: 0.56 | T10: 0.55 | U10: 0.2 | V10: -0.18 | W10: 2.03 | X10: 0.16 | Y10: 0 | Z10: 6.37 | AA10: -0.09 | AB10: 0.13 | AC10: -0.02 | AD10: -0.02 | AE10: 0.19 | AF10: 0.36 | AG10: 0.02 | AH10: 0.66 | AI10: 0.18 | AJ10: 1.37 | AK10: Distress | AL10: 0.19 | AM10: 0.36 | AN10: 0.02 | AO10: 0.66 | AP10: 0.18 | AQ10: 0.96 | AR10: Distress | AS10: 0.19 | AT10: 0.36 | AU10: 0.02 | AV10: 0.66 | AW10: 3.26 | AX10: Safe | AY10: 0.19 | AZ10: 0.02 | BA10: 0.6 | BB10: 0.18 | BC10: 0.73 | BD10: Distress | BE10: 0.02 | BF10: 0.56 | BG10: 5.81 | BH10: -1.2 | BI10: 0.23 | BJ10: Healthy | BK10: 1 | BL10: 1 | BM10: 1 | BN10: 1 | BO10: 1 | BP10: 0 | BQ10: 1 | BR10: 0 | BS10: 0 | BT10: 6 | BU10: Mixed | BV10: 1.24 | BW10: 0.67 | BX10: 0.95 | BY10: 0.91 | BZ10: 0.93 | CA10: 1.21 | CB10: 1.02 | CC10: -0.02 | CD10: -2.66 | CE10: Lower Risk | CF10: -2.95 | CG10: 50.81 | CH10: 0 | CI10: CLEAR
